Workbook

Sheet Model
A1: Pensionsalder model
A3: Input
A4: Levealder | B4: 95 | C4: aar
A5: Nuvaerende portefolje | B5: 7000000 | C5: kr
A6: Aarligt forbrug efter skat | B6: 800000 | C6: kr i dag
A7: Aarligt afkast REAL foer skat | B7: 0.07 | C7: %
A8: Skat paa afkast | B8: 0.22 | C8: %
A9: Skat paa udbetalinger | B9: 0.38 | C9: %
A10: Nuvaerende alder | B10: 35 | C10: aar
A11: Offentlig pensionsudbetaling start | B11: 73 | C11: aar
A12: Sats for offentlig pension foer skat | B12: 7544 | C12: kr pr maaned i dag
A13: Inflation til nominelle visninger | B13: 0.02 | C13: %
A14: Bijob efter pensionsalder foer skat | B14: 10000 | C14: kr pr maaned i dag
A15: Bijob varighed efter pensionsalder | B15: 10 | C15: aar
A17: Beregninger
A18: Aarligt realafkast efter skat | B18: =B7*(1-B8)
A19: Offentlig pension foer skat, aarligt | B19: =B12*12
A20: Offentlig pension efter skat, aarligt | B20: =B19*(1-B9)
A21: Bijob foer skat, aarligt | B21: =B14*12
A22: Bijob efter skat, aarligt | B22: =B21*(1-B9)
A23: Bijob varighed | B23: =B15
A24: Optimal pensionsalder | B24: =IFERROR(INDEX('Aarlig projektion'!A2:A122,MATCH(TRUE,'Aarlig projektion'!K2:K122,0)),"Ikke opnaaet")
A25: Portefolje ved optimal alder | B25: =IF(ISNUMBER(B24),INDEX('Aarlig projektion'!C2:C122,MATCH(B24,'Aarlig projektion'!A2:A122,0)),"")
A26: Behov ved optimal alder | B26: =IF(ISNUMBER(B24),INDEX('Aarlig projektion'!D2:D122,MATCH(B24,'Aarlig projektion'!A2:A122,0)),"")
A27: Margin ved optimal alder | B27: =IF(ISNUMBER(B24),B25-B26,"")
A29: Antagelser
A30: Alle hovedbeloeb er i realkroner, fordi afkastinput er realt.
A31: Offentlig pension antages fuldt inflationsjusteret, saa dens reale koebekraft er konstant.
A32: Bijob antages at starte ved pensionsalderen, loebe i det valgte antal aar og have konstant real koebekraft.
A33: Portefoljebehovet er brutto foer udbetalingsskat og beregnes, saa portefoljen er 0 kr ved slutningen af levealderen.
A34: Udbetalinger antages at ske ved starten af hvert pensionsaar; resterende saldo investeres fortsat.

Sheet Aarlig projektion
A1: Alder | B1: Aar fra nu | C1: Forventet portefolje | D1: Nodvendig portefolje | E1: Offentlig pension efter skat | F1: Bijob efter skat i foerste pensionsaar | G1: Samlet indkomst efter skat i foerste pensionsaar | H1: Nettoforbrug fra portefolje | I1: Brutto udbetaling fra portefolje | J1: Margin | K1: Kan pensioneres | L1: Offentlig pension nominelt foer skat | M1: Bijob nominelt foer skat i foerste pensionsaar | N1: PV behov +0 aar | O1: PV behov +1 aar | P1: PV behov +2 aar | Q1: PV behov +3 aar | R1: PV behov +4 aar | S1: PV behov +5 aar | T1: PV behov +6 aar | U1: PV behov +7 aar | V1: PV behov +8 aar | W1: PV behov +9 aar | X1: PV behov +10 aar | Y1: PV behov +11 aar | Z1: PV behov +12 aar | AA1: PV behov +13 aar | AB1: PV behov +14 aar | AC1: PV behov +15 aar | AD1: PV behov +16 aar | AE1: PV behov +17 aar | AF1: PV behov +18 aar | AG1: PV behov +19 aar | AH1: PV behov +20 aar | AI1: PV behov +21 aar | AJ1: PV behov +22 aar | AK1: PV behov +23 aar | AL1: PV behov +24 aar | AM1: PV behov +25 aar | AN1: PV behov +26 aar | AO1: PV behov +27 aar | AP1: PV behov +28 aar | AQ1: PV behov +29 aar | AR1: PV behov +30 aar | AS1: PV behov +31 aar | AT1: PV behov +32 aar | AU1: PV behov +33 aar | AV1: PV behov +34 aar | AW1: PV behov +35 aar | AX1: PV behov +36 aar | AY1: PV behov +37 aar | AZ1: PV behov +38 aar | BA1: PV behov +39 aar | BB1: PV behov +40 aar | BC1: PV behov +41 aar | BD1: PV behov +42 aar | BE1: PV behov +43 aar | BF1: PV behov +44 aar | BG1: PV behov +45 aar | BH1: PV behov +46 aar | BI1: PV behov +47 aar | BJ1: PV behov +48 aar | BK1: PV behov +49 aar | BL1: PV behov +50 aar | BM1: PV behov +51 aar | BN1: PV behov +52 aar | BO1: PV behov +53 aar | BP1: PV behov +54 aar | BQ1: PV behov +55 aar | BR1: PV behov +56 aar | BS1: PV behov +57 aar | BT1: PV behov +58 aar | BU1: PV behov +59 aar | BV1: PV behov +60 aar | BW1: PV behov +61 aar | BX1: PV behov +62 aar | BY1: PV behov +63 aar | BZ1: PV behov +64 aar | CA1: PV behov +65 aar | CB1: PV behov +66 aar | CC1: PV behov +67 aar | CD1: PV behov +68 aar | CE1: PV behov +69 aar | CF1: PV behov +70 aar | CG1: PV behov +71 aar | CH1: PV behov +72 aar | CI1: PV behov +73 aar | CJ1: PV behov +74 aar | CK1: PV behov +75 aar | CL1: PV behov +76 aar | CM1: PV behov +77 aar | CN1: PV behov +78 aar | CO1: PV behov +79 aar | CP1: PV behov +80 aar | CQ1: PV behov +81 aar | CR1: PV behov +82 aar | CS1: PV behov +83 aar | CT1: PV behov +84 aar | CU1: PV behov +85 aar | CV1: PV behov +86 aar | CW1: PV behov +87 aar | CX1: PV behov +88 aar | CY1: PV behov +89 aar | CZ1: PV behov +90 aar | DA1: PV behov +91 aar | DB1: PV behov +92 aar | DC1: PV behov +93 aar | DD1: PV behov +94 aar | DE1: PV behov +95 aar | DF1: PV behov +96 aar | DG1: PV behov +97 aar | DH1: PV behov +98 aar | DI1: PV behov +99 aar | DJ1: PV behov +100 aar | DK1: PV behov +101 aar | DL1: PV behov +102 aar | DM1: PV behov +103 aar | DN1: PV behov +104 aar | DO1: PV behov +105 aar | DP1: PV behov +106 aar | DQ1: PV behov +107 aar | DR1: PV behov +108 aar | DS1: PV behov +109 aar | DT1: PV behov +110 aar | DU1: PV behov +111 aar | DV1: PV behov +112 aar | DW1: PV behov +113 aar | DX1: PV behov +114 aar | DY1: PV behov +115 aar | DZ1: PV behov +116 aar | EA1: PV behov +117 aar | EB1: PV behov +118 aar | EC1: PV behov +119 aar | ED1: PV behov +120 aar
A2: =IF(Model!$B$10+ROW()-2<=Model!$B$4,Model!$B$10+ROW()-2,"") | B2: =IF(A2="","",A2-Model!$B$10) | C2: =IF(A2="","",Model!$B$5*(1+Model!$B$18)^B2) | D2: =IF(A2="","",SUM(N2:ED2)) | E2: =IF(A2="","",IF(A2>=Model!$B$11,Model!$B$20,0)) | F2: =IF(A2="","",IF(Model!$B$15>0,Model!$B$22,0)) | G2: =IF(A2="","",E2+F2) | H2: =IF(A2="","",MAX(0,Model!$B$6-G2)) | I2: =IF(A2="","",H2/(1-Model!$B$9)) | J2: =IF(A2="","",C2-D2) | K2: =IF(A2="","",C2>=D2) | L2: =IF(A2="","",IF(A2>=Model!$B$11,Model!$B$19*(1+Model!$B$13)^B2,0)) | M2: =IF(A2="","",IF(Model!$B$15>0,Model!$B$21*(1+Model!$B$13)^B2,0)) | N2: =IF(A2="","",IF((A2+0)>Model!$B$4,0,MAX(0,Model!$B$6-IF((A2+0)>=Model!$B$11,Model!$B$20,0)-IF(0<Model!$B$15,Model!$B$22,0))/(1-Model!$B$9)/(1+Model!$B$18)^0)) | O2: =IF(A2="","",IF((A2+1)>Model!$B$4,0,MAX(0,Model!$B$6-IF((A2+1)>=Model!$B$11,Model!$B$20,0)-IF(1<Model!$B$15,Model!$B$22,0))/(1-Model!$B$9)/(1+Model!$B$18)^1)) | P2: =IF(A2="","",IF((A2+2)>Model!$B$4,0,MAX(0,Model!$B$6-IF((A2+2)>=Model!$B$11,Model!$B$20,0)-IF(2<Model!$B$15,Model!$B$22,0))/(1-Model!$B$9)/(1+Model!$B$18)^2)) | Q2: =IF(A2="","",IF((A2+3)>Model!$B$4,0,MAX(0,Model!$B$6-IF((A2+3)>=Model!$B$11,Model!$B$20,0)-IF(3<Model!$B$15,Model!$B$22,0))/(1-Model!$B$9)/(1+Model!$B$18)^3)) | R2: =IF(A2="","",IF((A2+4)>Model!$B$4,0,MAX(0,Model!$B$6-IF((A2+4)>=Model!$B$11,Model!$B$20,0)-IF(4<Model!$B$15,Model!$B$22,0))/(1-Model!$B$9)/(1+Model!$B$18)^4)) | S2: =IF(A2="","",IF((A2+5)>Model!$B$4,0,MAX(0,Model!$B$6-IF((A2+5)>=Model!$B$11,Model!$B$20,0)-IF(5<Model!$B$15,Model!$B$22,0))/(1-Model!$B$9)/(1+Model!$B$18)^5)) | T2: =IF(A2="","",IF((A2+6)>Model!$B$4,0,MAX(0,Model!$B$6-IF((A2+6)>=Model!$B$11,Model!$B$20,0)-IF(6<Model!$B$15,Model!$B$22,0))/(1-Model!$B$9)/(1+Model!$B$18)^6)) | U2: =IF(A2="","",IF((A2+7)>Model!$B$4,0,MAX(0,Model!$B$6-IF((A2+7)>=Model!$B$11,Model!$B$20,0)-IF(7<Model!$B$15,Model!$B$22,0))/(1-Model!$B$9)/(1+Model!$B$18)^7)) | V2: =IF(A2="","",IF((A2+8)>Model!$B$4,0,MAX(0,Model!$B$6-IF((A2+8)>=Model!$B$11,Model!$B$20,0)-IF(8<Model!$B$15,Model!$B$22,0))/(1-Model!$B$9)/(1+Model!$B$18)^8)) | W2: =IF(A2="","",IF((A2+9)>Model!$B$4,0,MAX(0,Model!$B$6-IF((A2+9)>=Model!$B$11,Model!$B$20,0)-IF(9<Model!$B$15,Model!$B$22,0))/(1-Model!$B$9)/(1+Model!$B$18)^9)) | X2: =IF(A2="","",IF((A2+10)>Model!$B$4,0,MAX(0,Model!$B$6-IF((A2+10)>=Model!$B$11,Model!$B$20,0)-IF(10<Model!$B$15,Model!$B$22,0))/(1-Model!$B$9)/(1+Model!$B$18)^10)) | Y2: =IF(A2="","",IF((A2+11)>Model!$B$4,0,MAX(0,Model!$B$6-IF((A2+11)>=Model!$B$11,Model!$B$20,0)-IF(11<Model!$B$15,Model!$B$22,0))/(1-Model!$B$9)/(1+Model!$B$18)^11)) | Z2: =IF(A2="","",IF((A2+12)>Model!$B$4,0,MAX(0,Model!$B$6-IF((A2+12)>=Model!$B$11,Model!$B$20,0)-IF(12<Model!$B$15,Model!$B$22,0))/(1-Model!$B$9)/(1+Model!$B$18)^12)) | AA2: =IF(A2="","",IF((A2+13)>Model!$B$4,0,MAX(0,Model!$B$6-IF((A2+13)>=Model!$B$11,Model!$B$20,0)-IF(13<Model!$B$15,Model!$B$22,0))/(1-Model!$B$9)/(1+Model!$B$18)^13)) | AB2: =IF(A2="","",IF((A2+14)>Model!$B$4,0,MAX(0,Model!$B$6-IF((A2+14)>=Model!$B$11,Model!$B$20,0)-IF(14<Model!$B$15,Model!$B$22,0))/(1-Model!$B$9)/(1+Model!$B$18)^14)) | AC2: =IF(A2="","",IF((A2+15)>Model!$B$4,0,MAX(0,Model!$B$6-IF((A2+15)>=Model!$B$11,Model!$B$20,0)-IF(15<Model!$B$15,Model!$B$22,0))/(1-Model!$B$9)/(1+Model!$B$18)^15)) | AD2: =IF(A2="","",IF((A2+16)>Model!$B$4,0,MAX(0,Model!$B$6-IF((A2+16)>=Model!$B$11,Model!$B$20,0)-IF(16<Model!$B$15,Model!$B$22,0))/(1-Model!$B$9)/(1+Model!$B$18)^16)) | AE2: =IF(A2="","",IF((A2+17)>Model!$B$4,0,MAX(0,Model!$B$6-IF((A2+17)>=Model!$B$11,Model!$B$20,0)-IF(17<Model!$B$15,Model!$B$22,0))/(1-Model!$B$9)/(1+Model!$B$18)^17)) | AF2: =IF(A2="","",IF((A2+18)>Model!$B$4,0,MAX(0,Model!$B$6-IF((A2+18)>=Model!$B$11,Model!$B$20,0)-IF(18<Model!$B$15,Model!$B$22,0))/(1-Model!$B$9)/(1+Model!$B$18)^18)) | AG2: =IF(A2="","",IF((A2+19)>Model!$B$4,0,MAX(0,Model!$B$6-IF((A2+19)>=Model!$B$11,Model!$B$20,0)-IF(19<Model!$B$15,Model!$B$22,0))/(1-Model!$B$9)/(1+Model!$B$18)^19)) | AH2: =IF(A2="","",IF((A2+20)>Model!$B$4,0,MAX(0,Model!$B$6-IF((A2+20)>=Model!$B$11,Model!$B$20,0)-IF(20<Model!$B$15,Model!$B$22,0))/(1-Model!$B$9)/(1+Model!$B$18)^20)) | AI2: =IF(A2="","",IF((A2+21)>Model!$B$4,0,MAX(0,Model!$B$6-IF((A2+21)>=Model!$B$11,Model!$B$20,0)-IF(21<Model!$B$15,Model!$B$22,0))/(1-Model!$B$9)/(1+Model!$B$18)^21)) | AJ2: =IF(A2="","",IF((A2+22)>Model!$B$4,0,MAX(0,Model!$B$6-IF((A2+22)>=Model!$B$11,Model!$B$20,0)-IF(22<Model!$B$15,Model!$B$22,0))/(1-Model!$B$9)/(1+Model!$B$18)^22)) | AK2: =IF(A2="","",IF((A2+23)>Model!$B$4,0,MAX(0,Model!$B$6-IF((A2+23)>=Model!$B$11,Model!$B$20,0)-IF(23<Model!$B$15,Model!$B$22,0))/(1-Model!$B$9)/(1+Model!$B$18)^23)) | AL2: =IF(A2="","",IF((A2+24)>Model!$B$4,0,MAX(0,Model!$B$6-IF((A2+24)>=Model!$B$11,Model!$B$20,0)-IF(24<Model!$B$15,Model!$B$22,0))/(1-Model!$B$9)/(1+Model!$B$18)^24)) | AM2: =IF(A2="","",IF((A2+25)>Model!$B$4,0,MAX(0,Model!$B$6-IF((A2+25)>=Model!$B$11,Model!$B$20,0)-IF(25<Model!$B$15,Model!$B$22,0))/(1-Model!$B$9)/(1+Model!$B$18)^25)) | AN2: =IF(A2="","",IF((A2+26)>Model!$B$4,0,MAX(0,Model!$B$6-IF((A2+26)>=Model!$B$11,Model!$B$20,0)-IF(26<Model!$B$15,Model!$B$22,0))/(1-Model!$B$9)/(1+Model!$B$18)^26)) | AO2: =IF(A2="","",IF((A2+27)>Model!$B$4,0,MAX(0,Model!$B$6-IF((A2+27)>=Model!$B$11,Model!$B$20,0)-IF(27<Model!$B$15,Model!$B$22,0))/(1-Model!$B$9)/(1+Model!$B$18)^27)) | AP2: =IF(A2="","",IF((A2+28)>Model!$B$4,0,MAX(0,Model!$B$6-IF((A2+28)>=Model!$B$11,Model!$B$20,0)-IF(28<Model!$B$15,Model!$B$22,0))/(1-Model!$B$9)/(1+Model!$B$18)^28)) | AQ2: =IF(A2="","",IF((A2+29)>Model!$B$4,0,MAX(0,Model!$B$6-IF((A2+29)>=Model!$B$11,Model!$B$20,0)-IF(29<Model!$B$15,Model!$B$22,0))/(1-Model!$B$9)/(1+Model!$B$18)^29)) | AR2: =IF(A2="","",IF((A2+30)>Model!$B$4,0,MAX(0,Model!$B$6-IF((A2+30)>=Model!$B$11,Model!$B$20,0)-IF(30<Model!$B$15,Model!$B$22,0))/(1-Model!$B$9)/(1+Model!$B$18)^30)) | AS2: =IF(A2="","",IF((A2+31)>Model!$B$4,0,MAX(0,Model!$B$6-IF((A2+31)>=Model!$B$11,Model!$B$20,0)-IF(31<Model!$B$15,Model!$B$22,0))/(1-Model!$B$9)/(1+Model!$B$18)^31)) | AT2: =IF(A2="","",IF((A2+32)>Model!$B$4,0,MAX(0,Model!$B$6-IF((A2+32)>=Model!$B$11,Model!$B$20,0)-IF(32<Model!$B$15,Model!$B$22,0))/(1-Model!$B$9)/(1+Model!$B$18)^32)) | AU2: =IF(A2="","",IF((A2+33)>Model!$B$4,0,MAX(0,Model!$B$6-IF((A2+33)>=Model!$B$11,Model!$B$20,0)-IF(33<Model!$B$15,Model!$B$22,0))/(1-Model!$B$9)/(1+Model!$B$18)^33)) | AV2: =IF(A2="","",IF((A2+34)>Model!$B$4,0,MAX(0,Model!$B$6-IF((A2+34)>=Model!$B$11,Model!$B$20,0)-IF(34<Model!$B$15,Model!$B$22,0))/(1-Model!$B$9)/(1+Model!$B$18)^34)) | AW2: =IF(A2="","",IF((A2+35)>Model!$B$4,0,MAX(0,Model!$B$6-IF((A2+35)>=Model!$B$11,Model!$B$20,0)-IF(35<Model!$B$15,Model!$B$22,0))/(1-Model!$B$9)/(1+Model!$B$18)^35)) | AX2: =IF(A2="","",IF((A2+36)>Model!$B$4,0,MAX(0,Model!$B$6-IF((A2+36)>=Model!$B$11,Model!$B$20,0)-IF(36<Model!$B$15,Model!$B$22,0))/(1-Model!$B$9)/(1+Model!$B$18)^36)) | AY2: =IF(A2="","",IF((A2+37)>Model!$B$4,0,MAX(0,Model!$B$6-IF((A2+37)>=Model!$B$11,Model!$B$20,0)-IF(37<Model!$B$15,Model!$B$22,0))/(1-Model!$B$9)/(1+Model!$B$18)^37)) | AZ2: =IF(A2="","",IF((A2+38)>Model!$B$4,0,MAX(0,Model!$B$6-IF((A2+38)>=Model!$B$11,Model!$B$20,0)-IF(38<Model!$B$15,Model!$B$22,0))/(1-Model!$B$9)/(1+Model!$B$18)^38)) | BA2: =IF(A2="","",IF((A2+39)>Model!$B$4,0,MAX(0,Model!$B$6-IF((A2+39)>=Model!$B$11,Model!$B$20,0)-IF(39<Model!$B$15,Model!$B$22,0))/(1-Model!$B$9)/(1+Model!$B$18)^39)) | BB2: =IF(A2="","",IF((A2+40)>Model!$B$4,0,MAX(0,Model!$B$6-IF((A2+40)>=Model!$B$11,Model!$B$20,0)-IF(40<Model!$B$15,Model!$B$22,0))/(1-Model!$B$9)/(1+Model!$B$18)^40)) | BC2: =IF(A2="","",IF((A2+41)>Model!$B$4,0,MAX(0,Model!$B$6-IF((A2+41)>=Model!$B$11,Model!$B$20,0)-IF(41<Model!$B$15,Model!$B$22,0))/(1-Model!$B$9)/(1+Model!$B$18)^41)) | BD2: =IF(A2="","",IF((A2+42)>Model!$B$4,0,MAX(0,Model!$B$6-IF((A2+42)>=Model!$B$11,Model!$B$20,0)-IF(42<Model!$B$15,Model!$B$22,0))/(1-Model!$B$9)/(1+Model!$B$18)^42)) | BE2: =IF(A2="","",IF((A2+43)>Model!$B$4,0,MAX(0,Model!$B$6-IF((A2+43)>=Model!$B$11,Model!$B$20,0)-IF(43<Model!$B$15,Model!$B$22,0))/(1-Model!$B$9)/(1+Model!$B$18)^43)) | BF2: =IF(A2="","",IF((A2+44)>Model!$B$4,0,MAX(0,Model!$B$6-IF((A2+44)>=Model!$B$11,Model!$B$20,0)-IF(44<Model!$B$15,Model!$B$22,0))/(1-Model!$B$9)/(1+Model!$B$18)^44)) | BG2: =IF(A2="","",IF((A2+45)>Model!$B$4,0,MAX(0,Model!$B$6-IF((A2+45)>=Model!$B$11,Model!$B$20,0)-IF(45<Model!$B$15,Model!$B$22,0))/(1-Model!$B$9)/(1+Model!$B$18)^45)) | BH2: =IF(A2="","",IF((A2+46)>Model!$B$4,0,MAX(0,Model!$B$6-IF((A2+46)>=Model!$B$11,Model!$B$20,0)-IF(46<Model!$B$15,Model!$B$22,0))/(1-Model!$B$9)/(1+Model!$B$18)^46)) | BI2: =IF(A2="","",IF((A2+47)>Model!$B$4,0,MAX(0,Model!$B$6-IF((A2+47)>=Model!$B$11,Model!$B$20,0)-IF(47<Model!$B$15,Model!$B$22,0))/(1-Model!$B$9)/(1+Model!$B$18)^47)) | BJ2: =IF(A2="","",IF((A2+48)>Model!$B$4,0,MAX(0,Model!$B$6-IF((A2+48)>=Model!$B$11,Model!$B$20,0)-IF(48<Model!$B$15,Model!$B$22,0))/(1-Model!$B$9)/(1+Model!$B$18)^48)) | BK2: =IF(A2="","",IF((A2+49)>Model!$B$4,0,MAX(0,Model!$B$6-IF((A2+49)>=Model!$B$11,Model!$B$20,0)-IF(49<Model!$B$15,Model!$B$22,0))/(1-Model!$B$9)/(1+Model!$B$18)^49)) | BL2: =IF(A2="","",IF((A2+50)>Model!$B$4,0,MAX(0,Model!$B$6-IF((A2+50)>=Model!$B$11,Model!$B$20,0)-IF(50<Model!$B$15,Model!$B$22,0))/(1-Model!$B$9)/(1+Model!$B$18)^50)) | BM2: =IF(A2="","",IF((A2+51)>Model!$B$4,0,MAX(0,Model!$B$6-IF((A2+51)>=Model!$B$11,Model!$B$20,0)-IF(51<Model!$B$15,Model!$B$22,0))/(1-Model!$B$9)/(1+Model!$B$18)^51)) | BN2: =IF(A2="","",IF((A2+52)>Model!$B$4,0,MAX(0,Model!$B$6-IF((A2+52)>=Model!$B$11,Model!$B$20,0)-IF(52<Model!$B$15,Model!$B$22,0))/(1-Model!$B$9)/(1+Model!$B$18)^52)) | BO2: =IF(A2="","",IF((A2+53)>Model!$B$4,0,MAX(0,Model!$B$6-IF((A2+53)>=Model!$B$11,Model!$B$20,0)-IF(53<Model!$B$15,Model!$B$22,0))/(1-Model!$B$9)/(1+Model!$B$18)^53)) | BP2: =IF(A2="","",IF((A2+54)>Model!$B$4,0,MAX(0,Model!$B$6-IF((A2+54)>=Model!$B$11,Model!$B$20,0)-IF(54<Model!$B$15,Model!$B$22,0))/(1-Model!$B$9)/(1+Model!$B$18)^54)) | BQ2: =IF(A2="","",IF((A2+55)>Model!$B$4,0,MAX(0,Model!$B$6-IF((A2+55)>=Model!$B$11,Model!$B$20,0)-IF(55<Model!$B$15,Model!$B$22,0))/(1-Model!$B$9)/(1+Model!$B$18)^55)) | BR2: =IF(A2="","",IF((A2+56)>Model!$B$4,0,MAX(0,Model!$B$6-IF((A2+56)>=Model!$B$11,Model!$B$20,0)-IF(56<Model!$B$15,Model!$B$22,0))/(1-Model!$B$9)/(1+Model!$B$18)^56)) | BS2: =IF(A2="","",IF((A2+57)>Model!$B$4,0,MAX(0,Model!$B$6-IF((A2+57)>=Model!$B$11,Model!$B$20,0)-IF(57<Model!$B$15,Model!$B$22,0))/(1-Model!$B$9)/(1+Model!$B$18)^57)) | BT2: =IF(A2="","",IF((A2+58)>Model!$B$4,0,MAX(0,Model!$B$6-IF((A2+58)>=Model!$B$11,Model!$B$20,0)-IF(58<Model!$B$15,Model!$B$22,0))/(1-Model!$B$9)/(1+Model!$B$18)^58)) | BU2: =IF(A2="","",IF((A2+59)>Model!$B$4,0,MAX(0,Model!$B$6-IF((A2+59)>=Model!$B$11,Model!$B$20,0)-IF(59<Model!$B$15,Model!$B$22,0))/(1-Model!$B$9)/(1+Model!$B$18)^59)) | BV2: =IF(A2="","",IF((A2+60)>Model!$B$4,0,MAX(0,Model!$B$6-IF((A2+60)>=Model!$B$11,Model!$B$20,0)-IF(60<Model!$B$15,Model!$B$22,0))/(1-Model!$B$9)/(1+Model!$B$18)^60)) | BW2: =IF(A2="","",IF((A2+61)>Model!$B$4,0,MAX(0,Model!$B$6-IF((A2+61)>=Model!$B$11,Model!$B$20,0)-IF(61<Model!$B$15,Model!$B$22,0))/(1-Model!$B$9)/(1+Model!$B$18)^61)) | BX2: =IF(A2="","",IF((A2+62)>Model!$B$4,0,MAX(0,Model!$B$6-IF((A2+62)>=Model!$B$11,Model!$B$20,0)-IF(62<Model!$B$15,Model!$B$22,0))/(1-Model!$B$9)/(1+Model!$B$18)^62)) | BY2: =IF(A2="","",IF((A2+63)>Model!$B$4,0,MAX(0,Model!$B$6-IF((A2+63)>=Model!$B$11,Model!$B$20,0)-IF(63<Model!$B$15,Model!$B$22,0))/(1-Model!$B$9)/(1+Model!$B$18)^63)) | BZ2: =IF(A2="","",IF((A2+64)>Model!$B$4,0,MAX(0,Model!$B$6-IF((A2+64)>=Model!$B$11,Model!$B$20,0)-IF(64<Model!$B$15,Model!$B$22,0))/(1-Model!$B$9)/(1+Model!$B$18)^64)) | CA2: =IF(A2="","",IF((A2+65)>Model!$B$4,0,MAX(0,Model!$B$6-IF((A2+65)>=Model!$B$11,Model!$B$20,0)-IF(65<Model!$B$15,Model!$B$22,0))/(1-Model!$B$9)/(1+Model!$B$18)^65)) | CB2: =IF(A2="","",IF((A2+66)>Model!$B$4,0,MAX(0,Model!$B$6-IF((A2+66)>=Model!$B$11,Model!$B$20,0)-IF(66<Model!$B$15,Model!$B$22,0))/(1-Model!$B$9)/(1+Model!$B$18)^66)) | CC2: =IF(A2="","",IF((A2+67)>Model!$B$4,0,MAX(0,Model!$B$6-IF((A2+67)>=Model!$B$11,Model!$B$20,0)-IF(67<Model!$B$15,Model!$B$22,0))/(1-Model!$B$9)/(1+Model!$B$18)^67)) | CD2: =IF(A2="","",IF((A2+68)>Model!$B$4,0,MAX(0,Model!$B$6-IF((A2+68)>=Model!$B$11,Model!$B$20,0)-IF(68<Model!$B$15,Model!$B$22,0))/(1-Model!$B$9)/(1+Model!$B$18)^68)) | CE2: =IF(A2="","",IF((A2+69)>Model!$B$4,0,MAX(0,Model!$B$6-IF((A2+69)>=Model!$B$11,Model!$B$20,0)-IF(69<Model!$B$15,Model!$B$22,0))/(1-Model!$B$9)/(1+Model!$B$18)^69)) | CF2: =IF(A2="","",IF((A2+70)>Model!$B$4,0,MAX(0,Model!$B$6-IF((A2+70)>=Model!$B$11,Model!$B$20,0)-IF(70<Model!$B$15,Model!$B$22,0))/(1-Model!$B$9)/(1+Model!$B$18)^70)) | CG2: =IF(A2="","",IF((A2+71)>Model!$B$4,0,MAX(0,Model!$B$6-IF((A2+71)>=Model!$B$11,Model!$B$20,0)-IF(71<Model!$B$15,Model!$B$22,0))/(1-Model!$B$9)/(1+Model!$B$18)^71)) | CH2: =IF(A2="","",IF((A2+72)>Model!$B$4,0,MAX(0,Model!$B$6-IF((A2+72)>=Model!$B$11,Model!$B$20,0)-IF(72<Model!$B$15,Model!$B$22,0))/(1-Model!$B$9)/(1+Model!$B$18)^72)) | CI2: =IF(A2="","",IF((A2+73)>Model!$B$4,0,MAX(0,Model!$B$6-IF((A2+73)>=Model!$B$11,Model!$B$20,0)-IF(73<Model!$B$15,Model!$B$22,0))/(1-Model!$B$9)/(1+Model!$B$18)^73)) | CJ2: =IF(A2="","",IF((A2+74)>Model!$B$4,0,MAX(0,Model!$B$6-IF((A2+74)>=Model!$B$11,Model!$B$20,0)-IF(74<Model!$B$15,Model!$B$22,0))/(1-Model!$B$9)/(1+Model!$B$18)^74)) | CK2: =IF(A2="","",IF((A2+75)>Model!$B$4,0,MAX(0,Model!$B$6-IF((A2+75)>=Model!$B$11,Model!$B$20,0)-IF(75<Model!$B$15,Model!$B$22,0))/(1-Model!$B$9)/(1+Model!$B$18)^75)) | CL2: =IF(A2="","",IF((A2+76)>Model!$B$4,0,MAX(0,Model!$B$6-IF((A2+76)>=Model!$B$11,Model!$B$20,0)-IF(76<Model!$B$15,Model!$B$22,0))/(1-Model!$B$9)/(1+Model!$B$18)^76)) | CM2: =IF(A2="","",IF((A2+77)>Model!$B$4,0,MAX(0,Model!$B$6-IF((A2+77)>=Model!$B$11,Model!$B$20,0)-IF(77<Model!$B$15,Model!$B$22,0))/(1-Model!$B$9)/(1+Model!$B$18)^77)) | CN2: =IF(A2="","",IF((A2+78)>Model!$B$4,0,MAX(0,Model!$B$6-IF((A2+78)>=Model!$B$11,Model!$B$20,0)-IF(78<Model!$B$15,Model!$B$22,0))/(1-Model!$B$9)/(1+Model!$B$18)^78)) | CO2: =IF(A2="","",IF((A2+79)>Model!$B$4,0,MAX(0,Model!$B$6-IF((A2+79)>=Model!$B$11,Model!$B$20,0)-IF(79<Model!$B$15,Model!$B$22,0))/(1-Model!$B$9)/(1+Model!$B$18)^79)) | CP2: =IF(A2="","",IF((A2+80)>Model!$B$4,0,MAX(0,Model!$B$6-IF((A2+80)>=Model!$B$11,Model!$B$20,0)-IF(80<Model!$B$15,Model!$B$22,0))/(1-Model!$B$9)/(1+Model!$B$18)^80)) | CQ2: =IF(A2="","",IF((A2+81)>Model!$B$4,0,MAX(0,Model!$B$6-IF((A2+81)>=Model!$B$11,Model!$B$20,0)-IF(81<Model!$B$15,Model!$B$22,0))/(1-Model!$B$9)/(1+Model!$B$18)^81)) | CR2: =IF(A2="","",IF((A2+82)>Model!$B$4,0,MAX(0,Model!$B$6-IF((A2+82)>=Model!$B$11,Model!$B$20,0)-IF(82<Model!$B$15,Model!$B$22,0))/(1-Model!$B$9)/(1+Model!$B$18)^82)) | CS2: =IF(A2="","",IF((A2+83)>Model!$B$4,0,MAX(0,Model!$B$6-IF((A2+83)>=Model!$B$11,Model!$B$20,0)-IF(83<Model!$B$15,Model!$B$22,0))/(1-Model!$B$9)/(1+Model!$B$18)^83)) | CT2: =IF(A2="","",IF((A2+84)>Model!$B$4,0,MAX(0,Model!$B$6-IF((A2+84)>=Model!$B$11,Model!$B$20,0)-IF(84<Model!$B$15,Model!$B$22,0))/(1-Model!$B$9)/(1+Model!$B$18)^84)) | CU2: =IF(A2="","",IF((A2+85)>Model!$B$4,0,MAX(0,Model!$B$6-IF((A2+85)>=Model!$B$11,Model!$B$20,0)-IF(85<Model!$B$15,Model!$B$22,0))/(1-Model!$B$9)/(1+Model!$B$18)^85)) | CV2: =IF(A2="","",IF((A2+86)>Model!$B$4,0,MAX(0,Model!$B$6-IF((A2+86)>=Model!$B$11,Model!$B$20,0)-IF(86<Model!$B$15,Model!$B$22,0))/(1-Model!$B$9)/(1+Model!$B$18)^86)) | CW2: =IF(A2="","",IF((A2+87)>Model!$B$4,0,MAX(0,Model!$B$6-IF((A2+87)>=Model!$B$11,Model!$B$20,0)-IF(87<Model!$B$15,Model!$B$22,0))/(1-Model!$B$9)/(1+Model!$B$18)^87)) | CX2: =IF(A2="","",IF((A2+88)>Model!$B$4,0,MAX(0,Model!$B$6-IF((A2+88)>=Model!$B$11,Model!$B$20,0)-IF(88<Model!$B$15,Model!$B$22,0))/(1-Model!$B$9)/(1+Model!$B$18)^88)) | CY2: =IF(A2="","",IF((A2+89)>Model!$B$4,0,MAX(0,Model!$B$6-IF((A2+89)>=Model!$B$11,Model!$B$20,0)-IF(89<Model!$B$15,Model!$B$22,0))/(1-Model!$B$9)/(1+Model!$B$18)^89)) | CZ2: =IF(A2="","",IF((A2+90)>Model!$B$4,0,MAX(0,Model!$B$6-IF((A2+90)>=Model!$B$11,Model!$B$20,0)-IF(90<Model!$B$15,Model!$B$22,0))/(1-Model!$B$9)/(1+Model!$B$18)^90)) | DA2: =IF(A2="","",IF((A2+91)>Model!$B$4,0,MAX(0,Model!$B$6-IF((A2+91)>=Model!$B$11,Model!$B$20,0)-IF(91<Model!$B$15,Model!$B$22,0))/(1-Model!$B$9)/(1+Model!$B$18)^91)) | DB2: =IF(A2="","",IF((A2+92)>Model!$B$4,0,MAX(0,Model!$B$6-IF((A2+92)>=Model!$B$11,Model!$B$20,0)-IF(92<Model!$B$15,Model!$B$22,0))/(1-Model!$B$9)/(1+Model!$B$18)^92)) | DC2: =IF(A2="","",IF((A2+93)>Model!$B$4,0,MAX(0,Model!$B$6-IF((A2+93)>=Model!$B$11,Model!$B$20,0)-IF(93<Model!$B$15,Model!$B$22,0))/(1-Model!$B$9)/(1+Model!$B$18)^93)) | DD2: =IF(A2="","",IF((A2+94)>Model!$B$4,0,MAX(0,Model!$B$6-IF((A2+94)>=Model!$B$11,Model!$B$20,0)-IF(94<Model!$B$15,Model!$B$22,0))/(1-Model!$B$9)/(1+Model!$B$18)^94)) | DE2: =IF(A2="","",IF((A2+95)>Model!$B$4,0,MAX(0,Model!$B$6-IF((A2+95)>=Model!$B$11,Model!$B$20,0)-IF(95<Model!$B$15,Model!$B$22,0))/(1-Model!$B$9)/(1+Model!$B$18)^95)) | DF2: =IF(A2="","",IF((A2+96)>Model!$B$4,0,MAX(0,Model!$B$6-IF((A2+96)>=Model!$B$11,Model!$B$20,0)-IF(96<Model!$B$15,Model!$B$22,0))/(1-Model!$B$9)/(1+Model!$B$18)^96)) | DG2: =IF(A2="","",IF((A2+97)>Model!$B$4,0,MAX(0,Model!$B$6-IF((A2+97)>=Model!$B$11,Model!$B$20,0)-IF(97<Model!$B$15,Model!$B$22,0))/(1-Model!$B$9)/(1+Model!$B$18)^97)) | DH2: =IF(A2="","",IF((A2+98)>Model!$B$4,0,MAX(0,Model!$B$6-IF((A2+98)>=Model!$B$11,Model!$B$20,0)-IF(98<Model!$B$15,Model!$B$22,0))/(1-Model!$B$9)/(1+Model!$B$18)^98)) | DI2: =IF(A2="","",IF((A2+99)>Model!$B$4,0,MAX(0,Model!$B$6-IF((A2+99)>=Model!$B$11,Model!$B$20,0)-IF(99<Model!$B$15,Model!$B$22,0))/(1-Model!$B$9)/(1+Model!$B$18)^99)) | DJ2: =IF(A2="","",IF((A2+100)>Model!$B$4,0,MAX(0,Model!$B$6-IF((A2+100)>=Model!$B$11,Model!$B$20,0)-IF(100<Model!$B$15,Model!$B$22,0))/(1-Model!$B$9)/(1+Model!$B$18)^100)) | DK2: =IF(A2="","",IF((A2+101)>Model!$B$4,0,MAX(0,Model!$B$6-IF((A2+101)>=Model!$B$11,Model!$B$20,0)-IF(101<Model!$B$15,Model!$B$22,0))/(1-Model!$B$9)/(1+Model!$B$18)^101)) | DL2: =IF(A2="","",IF((A2+102)>Model!$B$4,0,MAX(0,Model!$B$6-IF((A2+102)>=Model!$B$11,Model!$B$20,0)-IF(102<Model!$B$15,Model!$B$22,0))/(1-Model!$B$9)/(1+Model!$B$18)^102)) | DM2: =IF(A2="","",IF((A2+103)>Model!$B$4,0,MAX(0,Model!$B$6-IF((A2+103)>=Model!$B$11,Model!$B$20,0)-IF(103<Model!$B$15,Model!$B$22,0))/(1-Model!$B$9)/(1+Model!$B$18)^103)) | DN2: =IF(A2="","",IF((A2+104)>Model!$B$4,0,MAX(0,Model!$B$6-IF((A2+104)>=Model!$B$11,Model!$B$20,0)-IF(104<Model!$B$15,Model!$B$22,0))/(1-Model!$B$9)/(1+Model!$B$18)^104)) | DO2: =IF(A2="","",IF((A2+105)>Model!$B$4,0,MAX(0,Model!$B$6-IF((A2+105)>=Model!$B$11,Model!$B$20,0)-IF(105<Model!$B$15,Model!$B$22,0))/(1-Model!$B$9)/(1+Model!$B$18)^105)) | DP2: =IF(A2="","",IF((A2+106)>Model!$B$4,0,MAX(0,Model!$B$6-IF((A2+106)>=Model!$B$11,Model!$B$20,0)-IF(106<Model!$B$15,Model!$B$22,0))/(1-Model!$B$9)/(1+Model!$B$18)^106)) | DQ2: =IF(A2="","",IF((A2+107)>Model!$B$4,0,MAX(0,Model!$B$6-IF((A2+107)>=Model!$B$11,Model!$B$20,0)-IF(107<Model!$B$15,Model!$B$22,0))/(1-Model!$B$9)/(1+Model!$B$18)^107)) | DR2: =IF(A2="","",IF((A2+108)>Model!$B$4,0,MAX(0,Model!$B$6-IF((A2+108)>=Model!$B$11,Model!$B$20,0)-IF(108<Model!$B$15,Model!$B$22,0))/(1-Model!$B$9)/(1+Model!$B$18)^108)) | DS2: =IF(A2="","",IF((A2+109)>Model!$B$4,0,MAX(0,Model!$B$6-IF((A2+109)>=Model!$B$11,Model!$B$20,0)-IF(109<Model!$B$15,Model!$B$22,0))/(1-Model!$B$9)/(1+Model!$B$18)^109)) | DT2: =IF(A2="","",IF((A2+110)>Model!$B$4,0,MAX(0,Model!$B$6-IF((A2+110)>=Model!$B$11,Model!$B$20,0)-IF(110<Model!$B$15,Model!$B$22,0))/(1-Model!$B$9)/(1+Model!$B$18)^110)) | DU2: =IF(A2="","",IF((A2+111)>Model!$B$4,0,MAX(0,Model!$B$6-IF((A2+111)>=Model!$B$11,Model!$B$20,0)-IF(111<Model!$B$15,Model!$B$22,0))/(1-Model!$B$9)/(1+Model!$B$18)^111)) | DV2: =IF(A2="","",IF((A2+112)>Model!$B$4,0,MAX(0,Model!$B$6-IF((A2+112)>=Model!$B$11,Model!$B$20,0)-IF(112<Model!$B$15,Model!$B$22,0))/(1-Model!$B$9)/(1+Model!$B$18)^112)) | DW2: =IF(A2="","",IF((A2+113)>Model!$B$4,0,MAX(0,Model!$B$6-IF((A2+113)>=Model!$B$11,Model!$B$20,0)-IF(113<Model!$B$15,Model!$B$22,0))/(1-Model!$B$9)/(1+Model!$B$18)^113)) | DX2: =IF(A2="","",IF((A2+114)>Model!$B$4,0,MAX(0,Model!$B$6-IF((A2+114)>=Model!$B$11,Model!$B$20,0)-IF(114<Model!$B$15,Model!$B$22,0))/(1-Model!$B$9)/(1+Model!$B$18)^114)) | DY2: =IF(A2="","",IF((A2+115)>Model!$B$4,0,MAX(0,Model!$B$6-IF((A2+115)>=Model!$B$11,Model!$B$20,0)-IF(115<Model!$B$15,Model!$B$22,0))/(1-Model!$B$9)/(1+Model!$B$18)^115)) | DZ2: =IF(A2="","",IF((A2+116)>Model!$B$4,0,MAX(0,Model!$B$6-IF((A2+116)>=Model!$B$11,Model!$B$20,0)-IF(116<Model!$B$15,Model!$B$22,0))/(1-Model!$B$9)/(1+Model!$B$18)^116)) | EA2: =IF(A2="","",IF((A2+117)>Model!$B$4,0,MAX(0,Model!$B$6-IF((A2+117)>=Model!$B$11,Model!$B$20,0)-IF(117<Model!$B$15,Model!$B$22,0))/(1-Model!$B$9)/(1+Model!$B$18)^117)) | EB2: =IF(A2="","",IF((A2+118)>Model!$B$4,0,MAX(0,Model!$B$6-IF((A2+118)>=Model!$B$11,Model!$B$20,0)-IF(118<Model!$B$15,Model!$B$22,0))/(1-Model!$B$9)/(1+Model!$B$18)^118)) | EC2: =IF(A2="","",IF((A2+119)>Model!$B$4,0,MAX(0,Model!$B$6-IF((A2+119)>=Model!$B$11,Model!$B$20,0)-IF(119<Model!$B$15,Model!$B$22,0))/(1-Model!$B$9)/(1+Model!$B$18)^119)) | ED2: =IF(A2="","",IF((A2+120)>Model!$B$4,0,MAX(0,Model!$B$6-IF((A2+120)>=Model!$B$11,Model!$B$20,0)-IF(120<Model!$B$15,Model!$B$22,0))/(1-Model!$B$9)/(1+Model!$B$18)^120))
A3: =IF(Model!$B$10+ROW()-2<=Model!$B$4,Model!$B$10+ROW()-2,"") | B3: =IF(A3="","",A3-Model!$B$10) | C3: =IF(A3="","",Model!$B$5*(1+Model!$B$18)^B3) | D3: =IF(A3="","",SUM(N3:ED3)) | E3: =IF(A3="","",IF(A3>=Model!$B$11,Model!$B$20,0)) | F3: =IF(A3="","",IF(Model!$B$15>0,Model!$B$22,0)) | G3: =IF(A3="","",E3+F3) | H3: =IF(A3="","",MAX(0,Model!$B$6-G3)) | I3: =IF(A3="","",H3/(1-Model!$B$9)) | J3: =IF(A3="","",C3-D3) | K3: =IF(A3="","",C3>=D3) | L3: =IF(A3="","",IF(A3>=Model!$B$11,Model!$B$19*(1+Model!$B$13)^B3,0)) | M3: =IF(A3="","",IF(Model!$B$15>0,Model!$B$21*(1+Model!$B$13)^B3,0)) | N3: =IF(A3="","",IF((A3+0)>Model!$B$4,0,MAX(0,Model!$B$6-IF((A3+0)>=Model!$B$11,Model!$B$20,0)-IF(0<Model!$B$15,Model!$B$22,0))/(1-Model!$B$9)/(1+Model!$B$18)^0)) | O3: =IF(A3="","",IF((A3+1)>Model!$B$4,0,MAX(0,Model!$B$6-IF((A3+1)>=Model!$B$11,Model!$B$20,0)-IF(1<Model!$B$15,Model!$B$22,0))/(1-Model!$B$9)/(1+Model!$B$18)^1)) | P3: =IF(A3="","",IF((A3+2)>Model!$B$4,0,MAX(0,Model!$B$6-IF((A3+2)>=Model!$B$11,Model!$B$20,0)-IF(2<Model!$B$15,Model!$B$22,0))/(1-Model!$B$9)/(1+Model!$B$18)^2)) | Q3: =IF(A3="","",IF((A3+3)>Model!$B$4,0,MAX(0,Model!$B$6-IF((A3+3)>=Model!$B$11,Model!$B$20,0)-IF(3<Model!$B$15,Model!$B$22,0))/(1-Model!$B$9)/(1+Model!$B$18)^3)) | R3: =IF(A3="","",IF((A3+4)>Model!$B$4,0,MAX(0,Model!$B$6-IF((A3+4)>=Model!$B$11,Model!$B$20,0)-IF(4<Model!$B$15,Model!$B$22,0))/(1-Model!$B$9)/(1+Model!$B$18)^4)) | S3: =IF(A3="","",IF((A3+5)>Model!$B$4,0,MAX(0,Model!$B$6-IF((A3+5)>=Model!$B$11,Model!$B$20,0)-IF(5<Model!$B$15,Model!$B$22,0))/(1-Model!$B$9)/(1+Model!$B$18)^5)) | T3: =IF(A3="","",IF((A3+6)>Model!$B$4,0,MAX(0,Model!$B$6-IF((A3+6)>=Model!$B$11,Model!$B$20,0)-IF(6<Model!$B$15,Model!$B$22,0))/(1-Model!$B$9)/(1+Model!$B$18)^6)) | U3: =IF(A3="","",IF((A3+7)>Model!$B$4,0,MAX(0,Model!$B$6-IF((A3+7)>=Model!$B$11,Model!$B$20,0)-IF(7<Model!$B$15,Model!$B$22,0))/(1-Model!$B$9)/(1+Model!$B$18)^7)) | V3: =IF(A3="","",IF((A3+8)>Model!$B$4,0,MAX(0,Model!$B$6-IF((A3+8)>=Model!$B$11,Model!$B$20,0)-IF(8<Model!$B$15,Model!$B$22,0))/(1-Model!$B$9)/(1+Model!$B$18)^8)) | W3: =IF(A3="","",IF((A3+9)>Model!$B$4,0,MAX(0,Model!$B$6-IF((A3+9)>=Model!$B$11,Model!$B$20,0)-IF(9<Model!$B$15,Model!$B$22,0))/(1-Model!$B$9)/(1+Model!$B$18)^9)) | X3: =IF(A3="","",IF((A3+10)>Model!$B$4,0,MAX(0,Model!$B$6-IF((A3+10)>=Model!$B$11,Model!$B$20,0)-IF(10<Model!$B$15,Model!$B$22,0))/(1-Model!$B$9)/(1+Model!$B$18)^10)) | Y3: =IF(A3="","",IF((A3+11)>Model!$B$4,0,MAX(0,Model!$B$6-IF((A3+11)>=Model!$B$11,Model!$B$20,0)-IF(11<Model!$B$15,Model!$B$22,0))/(1-Model!$B$9)/(1+Model!$B$18)^11)) | Z3: =IF(A3="","",IF((A3+12)>Model!$B$4,0,MAX(0,Model!$B$6-IF((A3+12)>=Model!$B$11,Model!$B$20,0)-IF(12<Model!$B$15,Model!$B$22,0))/(1-Model!$B$9)/(1+Model!$B$18)^12)) | AA3: =IF(A3="","",IF((A3+13)>Model!$B$4,0,MAX(0,Model!$B$6-IF((A3+13)>=Model!$B$11,Model!$B$20,0)-IF(13<Model!$B$15,Model!$B$22,0))/(1-Model!$B$9)/(1+Model!$B$18)^13)) | AB3: =IF(A3="","",IF((A3+14)>Model!$B$4,0,MAX(0,Model!$B$6-IF((A3+14)>=Model!$B$11,Model!$B$20,0)-IF(14<Model!$B$15,Model!$B$22,0))/(1-Model!$B$9)/(1+Model!$B$18)^14)) | AC3: =IF(A3="","",IF((A3+15)>Model!$B$4,0,MAX(0,Model!$B$6-IF((A3+15)>=Model!$B$11,Model!$B$20,0)-IF(15<Model!$B$15,Model!$B$22,0))/(1-Model!$B$9)/(1+Model!$B$18)^15)) | AD3: =IF(A3="","",IF((A3+16)>Model!$B$4,0,MAX(0,Model!$B$6-IF((A3+16)>=Model!$B$11,Model!$B$20,0)-IF(16<Model!$B$15,Model!$B$22,0))/(1-Model!$B$9)/(1+Model!$B$18)^16)) | AE3: =IF(A3="","",IF((A3+17)>Model!$B$4,0,MAX(0,Model!$B$6-IF((A3+17)>=Model!$B$11,Model!$B$20,0)-IF(17<Model!$B$15,Model!$B$22,0))/(1-Model!$B$9)/(1+Model!$B$18)^17)) | AF3: =IF(A3="","",IF((A3+18)>Model!$B$4,0,MAX(0,Model!$B$6-IF((A3+18)>=Model!$B$11,Model!$B$20,0)-IF(18<Model!$B$15,Model!$B$22,0))/(1-Model!$B$9)/(1+Model!$B$18)^18)) | AG3: =IF(A3="","",IF((A3+19)>Model!$B$4,0,MAX(0,Model!$B$6-IF((A3+19)>=Model!$B$11,Model!$B$20,0)-IF(19<Model!$B$15,Model!$B$22,0))/(1-Model!$B$9)/(1+Model!$B$18)^19)) | AH3: =IF(A3="","",IF((A3+20)>Model!$B$4,0,MAX(0,Model!$B$6-IF((A3+20)>=Model!$B$11,Model!$B$20,0)-IF(20<Model!$B$15,Model!$B$22,0))/(1-Model!$B$9)/(1+Model!$B$18)^20)) | AI3: =IF(A3="","",IF((A3+21)>Model!$B$4,0,MAX(0,Model!$B$6-IF((A3+21)>=Model!$B$11,Model!$B$20,0)-IF(21<Model!$B$15,Model!$B$22,0))/(1-Model!$B$9)/(1+Model!$B$18)^21)) | AJ3: =IF(A3="","",IF((A3+22)>Model!$B$4,0,MAX(0,Model!$B$6-IF((A3+22)>=Model!$B$11,Model!$B$20,0)-IF(22<Model!$B$15,Model!$B$22,0))/(1-Model!$B$9)/(1+Model!$B$18)^22)) | AK3: =IF(A3="","",IF((A3+23)>Model!$B$4,0,MAX(0,Model!$B$6-IF((A3+23)>=Model!$B$11,Model!$B$20,0)-IF(23<Model!$B$15,Model!$B$22,0))/(1-Model!$B$9)/(1+Model!$B$18)^23)) | AL3: =IF(A3="","",IF((A3+24)>Model!$B$4,0,MAX(0,Model!$B$6-IF((A3+24)>=Model!$B$11,Model!$B$20,0)-IF(24<Model!$B$15,Model!$B$22,0))/(1-Model!$B$9)/(1+Model!$B$18)^24)) | AM3: =IF(A3="","",IF((A3+25)>Model!$B$4,0,MAX(0,Model!$B$6-IF((A3+25)>=Model!$B$11,Model!$B$20,0)-IF(25<Model!$B$15,Model!$B$22,0))/(1-Model!$B$9)/(1+Model!$B$18)^25)) | AN3: =IF(A3="","",IF((A3+26)>Model!$B$4,0,MAX(0,Model!$B$6-IF((A3+26)>=Model!$B$11,Model!$B$20,0)-IF(26<Model!$B$15,Model!$B$22,0))/(1-Model!$B$9)/(1+Model!$B$18)^26)) | AO3: =IF(A3="","",IF((A3+27)>Model!$B$4,0,MAX(0,Model!$B$6-IF((A3+27)>=Model!$B$11,Model!$B$20,0)-IF(27<Model!$B$15,Model!$B$22,0))/(1-Model!$B$9)/(1+Model!$B$18)^27)) | AP3: =IF(A3="","",IF((A3+28)>Model!$B$4,0,MAX(0,Model!$B$6-IF((A3+28)>=Model!$B$11,Model!$B$20,0)-IF(28<Model!$B$15,Model!$B$22,0))/(1-Model!$B$9)/(1+Model!$B$18)^28)) | AQ3: =IF(A3="","",IF((A3+29)>Model!$B$4,0,MAX(0,Model!$B$6-IF((A3+29)>=Model!$B$11,Model!$B$20,0)-IF(29<Model!$B$15,Model!$B$22,0))/(1-Model!$B$9)/(1+Model!$B$18)^29)) | AR3: =IF(A3="","",IF((A3+30)>Model!$B$4,0,MAX(0,Model!$B$6-IF((A3+30)>=Model!$B$11,Model!$B$20,0)-IF(30<Model!$B$15,Model!$B$22,0))/(1-Model!$B$9)/(1+Model!$B$18)^30)) | AS3: =IF(A3="","",IF((A3+31)>Model!$B$4,0,MAX(0,Model!$B$6-IF((A3+31)>=Model!$B$11,Model!$B$20,0)-IF(31<Model!$B$15,Model!$B$22,0))/(1-Model!$B$9)/(1+Model!$B$18)^31)) | AT3: =IF(A3="","",IF((A3+32)>Model!$B$4,0,MAX(0,Model!$B$6-IF((A3+32)>=Model!$B$11,Model!$B$20,0)-IF(32<Model!$B$15,Model!$B$22,0))/(1-Model!$B$9)/(1+Model!$B$18)^32)) | AU3: =IF(A3="","",IF((A3+33)>Model!$B$4,0,MAX(0,Model!$B$6-IF((A3+33)>=Model!$B$11,Model!$B$20,0)-IF(33<Model!$B$15,Model!$B$22,0))/(1-Model!$B$9)/(1+Model!$B$18)^33)) | AV3: =IF(A3="","",IF((A3+34)>Model!$B$4,0,MAX(0,Model!$B$6-IF((A3+34)>=Model!$B$11,Model!$B$20,0)-IF(34<Model!$B$15,Model!$B$22,0))/(1-Model!$B$9)/(1+Model!$B$18)^34)) | AW3: =IF(A3="","",IF((A3+35)>Model!$B$4,0,MAX(0,Model!$B$6-IF((A3+35)>=Model!$B$11,Model!$B$20,0)-IF(35<Model!$B$15,Model!$B$22,0))/(1-Model!$B$9)/(1+Model!$B$18)^35)) | AX3: =IF(A3="","",IF((A3+36)>Model!$B$4,0,MAX(0,Model!$B$6-IF((A3+36)>=Model!$B$11,Model!$B$20,0)-IF(36<Model!$B$15,Model!$B$22,0))/(1-Model!$B$9)/(1+Model!$B$18)^36)) | AY3: =IF(A3="","",IF((A3+37)>Model!$B$4,0,MAX(0,Model!$B$6-IF((A3+37)>=Model!$B$11,Model!$B$20,0)-IF(37<Model!$B$15,Model!$B$22,0))/(1-Model!$B$9)/(1+Model!$B$18)^37)) | AZ3: =IF(A3="","",IF((A3+38)>Model!$B$4,0,MAX(0,Model!$B$6-IF((A3+38)>=Model!$B$11,Model!$B$20,0)-IF(38<Model!$B$15,Model!$B$22,0))/(1-Model!$B$9)/(1+Model!$B$18)^38)) | BA3: =IF(A3="","",IF((A3+39)>Model!$B$4,0,MAX(0,Model!$B$6-IF((A3+39)>=Model!$B$11,Model!$B$20,0)-IF(39<Model!$B$15,Model!$B$22,0))/(1-Model!$B$9)/(1+Model!$B$18)^39)) | BB3: =IF(A3="","",IF((A3+40)>Model!$B$4,0,MAX(0,Model!$B$6-IF((A3+40)>=Model!$B$11,Model!$B$20,0)-IF(40<Model!$B$15,Model!$B$22,0))/(1-Model!$B$9)/(1+Model!$B$18)^40)) | BC3: =IF(A3="","",IF((A3+41)>Model!$B$4,0,MAX(0,Model!$B$6-IF((A3+41)>=Model!$B$11,Model!$B$20,0)-IF(41<Model!$B$15,Model!$B$22,0))/(1-Model!$B$9)/(1+Model!$B$18)^41)) | BD3: =IF(A3="","",IF((A3+42)>Model!$B$4,0,MAX(0,Model!$B$6-IF((A3+42)>=Model!$B$11,Model!$B$20,0)-IF(42<Model!$B$15,Model!$B$22,0))/(1-Model!$B$9)/(1+Model!$B$18)^42)) | BE3: =IF(A3="","",IF((A3+43)>Model!$B$4,0,MAX(0,Model!$B$6-IF((A3+43)>=Model!$B$11,Model!$B$20,0)-IF(43<Model!$B$15,Model!$B$22,0))/(1-Model!$B$9)/(1+Model!$B$18)^43)) | BF3: =IF(A3="","",IF((A3+44)>Model!$B$4,0,MAX(0,Model!$B$6-IF((A3+44)>=Model!$B$11,Model!$B$20,0)-IF(44<Model!$B$15,Model!$B$22,0))/(1-Model!$B$9)/(1+Model!$B$18)^44)) | BG3: =IF(A3="","",IF((A3+45)>Model!$B$4,0,MAX(0,Model!$B$6-IF((A3+45)>=Model!$B$11,Model!$B$20,0)-IF(45<Model!$B$15,Model!$B$22,0))/(1-Model!$B$9)/(1+Model!$B$18)^45)) | BH3: =IF(A3="","",IF((A3+46)>Model!$B$4,0,MAX(0,Model!$B$6-IF((A3+46)>=Model!$B$11,Model!$B$20,0)-IF(46<Model!$B$15,Model!$B$22,0))/(1-Model!$B$9)/(1+Model!$B$18)^46)) | BI3: =IF(A3="","",IF((A3+47)>Model!$B$4,0,MAX(0,Model!$B$6-IF((A3+47)>=Model!$B$11,Model!$B$20,0)-IF(47<Model!$B$15,Model!$B$22,0))/(1-Model!$B$9)/(1+Model!$B$18)^47)) | BJ3: =IF(A3="","",IF((A3+48)>Model!$B$4,0,MAX(0,Model!$B$6-IF((A3+48)>=Model!$B$11,Model!$B$20,0)-IF(48<Model!$B$15,Model!$B$22,0))/(1-Model!$B$9)/(1+Model!$B$18)^48)) | BK3: =IF(A3="","",IF((A3+49)>Model!$B$4,0,MAX(0,Model!$B$6-IF((A3+49)>=Model!$B$11,Model!$B$20,0)-IF(49<Model!$B$15,Model!$B$22,0))/(1-Model!$B$9)/(1+Model!$B$18)^49)) | BL3: =IF(A3="","",IF((A3+50)>Model!$B$4,0,MAX(0,Model!$B$6-IF((A3+50)>=Model!$B$11,Model!$B$20,0)-IF(50<Model!$B$15,Model!$B$22,0))/(1-Model!$B$9)/(1+Model!$B$18)^50)) | BM3: =IF(A3="","",IF((A3+51)>Model!$B$4,0,MAX(0,Model!$B$6-IF((A3+51)>=Model!$B$11,Model!$B$20,0)-IF(51<Model!$B$15,Model!$B$22,0))/(1-Model!$B$9)/(1+Model!$B$18)^51)) | BN3: =IF(A3="","",IF((A3+52)>Model!$B$4,0,MAX(0,Model!$B$6-IF((A3+52)>=Model!$B$11,Model!$B$20,0)-IF(52<Model!$B$15,Model!$B$22,0))/(1-Model!$B$9)/(1+Model!$B$18)^52)) | BO3: =IF(A3="","",IF((A3+53)>Model!$B$4,0,MAX(0,Model!$B$6-IF((A3+53)>=Model!$B$11,Model!$B$20,0)-IF(53<Model!$B$15,Model!$B$22,0))/(1-Model!$B$9)/(1+Model!$B$18)^53)) | BP3: =IF(A3="","",IF((A3+54)>Model!$B$4,0,MAX(0,Model!$B$6-IF((A3+54)>=Model!$B$11,Model!$B$20,0)-IF(54<Model!$B$15,Model!$B$22,0))/(1-Model!$B$9)/(1+Model!$B$18)^54)) | BQ3: =IF(A3="","",IF((A3+55)>Model!$B$4,0,MAX(0,Model!$B$6-IF((A3+55)>=Model!$B$11,Model!$B$20,0)-IF(55<Model!$B$15,Model!$B$22,0))/(1-Model!$B$9)/(1+Model!$B$18)^55)) | BR3: =IF(A3="","",IF((A3+56)>Model!$B$4,0,MAX(0,Model!$B$6-IF((A3+56)>=Model!$B$11,Model!$B$20,0)-IF(56<Model!$B$15,Model!$B$22,0))/(1-Model!$B$9)/(1+Model!$B$18)^56)) | BS3: =IF(A3="","",IF((A3+57)>Model!$B$4,0,MAX(0,Model!$B$6-IF((A3+57)>=Model!$B$11,Model!$B$20,0)-IF(57<Model!$B$15,Model!$B$22,0))/(1-Model!$B$9)/(1+Model!$B$18)^57)) | BT3: =IF(A3="","",IF((A3+58)>Model!$B$4,0,MAX(0,Model!$B$6-IF((A3+58)>=Model!$B$11,Model!$B$20,0)-IF(58<Model!$B$15,Model!$B$22,0))/(1-Model!$B$9)/(1+Model!$B$18)^58)) | BU3: =IF(A3="","",IF((A3+59)>Model!$B$4,0,MAX(0,Model!$B$6-IF((A3+59)>=Model!$B$11,Model!$B$20,0)-IF(59<Model!$B$15,Model!$B$22,0))/(1-Model!$B$9)/(1+Model!$B$18)^59)) | BV3: =IF(A3="","",IF((A3+60)>Model!$B$4,0,MAX(0,Model!$B$6-IF((A3+60)>=Model!$B$11,Model!$B$20,0)-IF(60<Model!$B$15,Model!$B$22,0))/(1-Model!$B$9)/(1+Model!$B$18)^60)) | BW3: =IF(A3="","",IF((A3+61)>Model!$B$4,0,MAX(0,Model!$B$6-IF((A3+61)>=Model!$B$11,Model!$B$20,0)-IF(61<Model!$B$15,Model!$B$22,0))/(1-Model!$B$9)/(1+Model!$B$18)^61)) | BX3: =IF(A3="","",IF((A3+62)>Model!$B$4,0,MAX(0,Model!$B$6-IF((A3+62)>=Model!$B$11,Model!$B$20,0)-IF(62<Model!$B$15,Model!$B$22,0))/(1-Model!$B$9)/(1+Model!$B$18)^62)) | BY3: =IF(A3="","",IF((A3+63)>Model!$B$4,0,MAX(0,Model!$B$6-IF((A3+63)>=Model!$B$11,Model!$B$20,0)-IF(63<Model!$B$15,Model!$B$22,0))/(1-Model!$B$9)/(1+Model!$B$18)^63)) | BZ3: =IF(A3="","",IF((A3+64)>Model!$B$4,0,MAX(0,Model!$B$6-IF((A3+64)>=Model!$B$11,Model!$B$20,0)-IF(64<Model!$B$15,Model!$B$22,0))/(1-Model!$B$9)/(1+Model!$B$18)^64)) | CA3: =IF(A3="","",IF((A3+65)>Model!$B$4,0,MAX(0,Model!$B$6-IF((A3+65)>=Model!$B$11,Model!$B$20,0)-IF(65<Model!$B$15,Model!$B$22,0))/(1-Model!$B$9)/(1+Model!$B$18)^65)) | CB3: =IF(A3="","",IF((A3+66)>Model!$B$4,0,MAX(0,Model!$B$6-IF((A3+66)>=Model!$B$11,Model!$B$20,0)-IF(66<Model!$B$15,Model!$B$22,0))/(1-Model!$B$9)/(1+Model!$B$18)^66)) | CC3: =IF(A3="","",IF((A3+67)>Model!$B$4,0,MAX(0,Model!$B$6-IF((A3+67)>=Model!$B$11,Model!$B$20,0)-IF(67<Model!$B$15,Model!$B$22,0))/(1-Model!$B$9)/(1+Model!$B$18)^67)) | CD3: =IF(A3="","",IF((A3+68)>Model!$B$4,0,MAX(0,Model!$B$6-IF((A3+68)>=Model!$B$11,Model!$B$20,0)-IF(68<Model!$B$15,Model!$B$22,0))/(1-Model!$B$9)/(1+Model!$B$18)^68)) | CE3: =IF(A3="","",IF((A3+69)>Model!$B$4,0,MAX(0,Model!$B$6-IF((A3+69)>=Model!$B$11,Model!$B$20,0)-IF(69<Model!$B$15,Model!$B$22,0))/(1-Model!$B$9)/(1+Model!$B$18)^69)) | CF3: =IF(A3="","",IF((A3+70)>Model!$B$4,0,MAX(0,Model!$B$6-IF((A3+70)>=Model!$B$11,Model!$B$20,0)-IF(70<Model!$B$15,Model!$B$22,0))/(1-Model!$B$9)/(1+Model!$B$18)^70)) | CG3: =IF(A3="","",IF((A3+71)>Model!$B$4,0,MAX(0,Model!$B$6-IF((A3+71)>=Model!$B$11,Model!$B$20,0)-IF(71<Model!$B$15,Model!$B$22,0))/(1-Model!$B$9)/(1+Model!$B$18)^71)) | CH3: =IF(A3="","",IF((A3+72)>Model!$B$4,0,MAX(0,Model!$B$6-IF((A3+72)>=Model!$B$11,Model!$B$20,0)-IF(72<Model!$B$15,Model!$B$22,0))/(1-Model!$B$9)/(1+Model!$B$18)^72)) | CI3: =IF(A3="","",IF((A3+73)>Model!$B$4,0,MAX(0,Model!$B$6-IF((A3+73)>=Model!$B$11,Model!$B$20,0)-IF(73<Model!$B$15,Model!$B$22,0))/(1-Model!$B$9)/(1+Model!$B$18)^73)) | CJ3: =IF(A3="","",IF((A3+74)>Model!$B$4,0,MAX(0,Model!$B$6-IF((A3+74)>=Model!$B$11,Model!$B$20,0)-IF(74<Model!$B$15,Model!$B$22,0))/(1-Model!$B$9)/(1+Model!$B$18)^74)) | CK3: =IF(A3="","",IF((A3+75)>Model!$B$4,0,MAX(0,Model!$B$6-IF((A3+75)>=Model!$B$11,Model!$B$20,0)-IF(75<Model!$B$15,Model!$B$22,0))/(1-Model!$B$9)/(1+Model!$B$18)^75)) | CL3: =IF(A3="","",IF((A3+76)>Model!$B$4,0,MAX(0,Model!$B$6-IF((A3+76)>=Model!$B$11,Model!$B$20,0)-IF(76<Model!$B$15,Model!$B$22,0))/(1-Model!$B$9)/(1+Model!$B$18)^76)) | CM3: =IF(A3="","",IF((A3+77)>Model!$B$4,0,MAX(0,Model!$B$6-IF((A3+77)>=Model!$B$11,Model!$B$20,0)-IF(77<Model!$B$15,Model!$B$22,0))/(1-Model!$B$9)/(1+Model!$B$18)^77)) | CN3: =IF(A3="","",IF((A3+78)>Model!$B$4,0,MAX(0,Model!$B$6-IF((A3+78)>=Model!$B$11,Model!$B$20,0)-IF(78<Model!$B$15,Model!$B$22,0))/(1-Model!$B$9)/(1+Model!$B$18)^78)) | CO3: =IF(A3="","",IF((A3+79)>Model!$B$4,0,MAX(0,Model!$B$6-IF((A3+79)>=Model!$B$11,Model!$B$20,0)-IF(79<Model!$B$15,Model!$B$22,0))/(1-Model!$B$9)/(1+Model!$B$18)^79)) | CP3: =IF(A3="","",IF((A3+80)>Model!$B$4,0,MAX(0,Model!$B$6-IF((A3+80)>=Model!$B$11,Model!$B$20,0)-IF(80<Model!$B$15,Model!$B$22,0))/(1-Model!$B$9)/(1+Model!$B$18)^80)) | CQ3: =IF(A3="","",IF((A3+81)>Model!$B$4,0,MAX(0,Model!$B$6-IF((A3+81)>=Model!$B$11,Model!$B$20,0)-IF(81<Model!$B$15,Model!$B$22,0))/(1-Model!$B$9)/(1+Model!$B$18)^81)) | CR3: =IF(A3="","",IF((A3+82)>Model!$B$4,0,MAX(0,Model!$B$6-IF((A3+82)>=Model!$B$11,Model!$B$20,0)-IF(82<Model!$B$15,Model!$B$22,0))/(1-Model!$B$9)/(1+Model!$B$18)^82)) | CS3: =IF(A3="","",IF((A3+83)>Model!$B$4,0,MAX(0,Model!$B$6-IF((A3+83)>=Model!$B$11,Model!$B$20,0)-IF(83<Model!$B$15,Model!$B$22,0))/(1-Model!$B$9)/(1+Model!$B$18)^83)) | CT3: =IF(A3="","",IF((A3+84)>Model!$B$4,0,MAX(0,Model!$B$6-IF((A3+84)>=Model!$B$11,Model!$B$20,0)-IF(84<Model!$B$15,Model!$B$22,0))/(1-Model!$B$9)/(1+Model!$B$18)^84)) | CU3: =IF(A3="","",IF((A3+85)>Model!$B$4,0,MAX(0,Model!$B$6-IF((A3+85)>=Model!$B$11,Model!$B$20,0)-IF(85<Model!$B$15,Model!$B$22,0))/(1-Model!$B$9)/(1+Model!$B$18)^85)) | CV3: =IF(A3="","",IF((A3+86)>Model!$B$4,0,MAX(0,Model!$B$6-IF((A3+86)>=Model!$B$11,Model!$B$20,0)-IF(86<Model!$B$15,Model!$B$22,0))/(1-Model!$B$9)/(1+Model!$B$18)^86)) | CW3: =IF(A3="","",IF((A3+87)>Model!$B$4,0,MAX(0,Model!$B$6-IF((A3+87)>=Model!$B$11,Model!$B$20,0)-IF(87<Model!$B$15,Model!$B$22,0))/(1-Model!$B$9)/(1+Model!$B$18)^87)) | CX3: =IF(A3="","",IF((A3+88)>Model!$B$4,0,MAX(0,Model!$B$6-IF((A3+88)>=Model!$B$11,Model!$B$20,0)-IF(88<Model!$B$15,Model!$B$22,0))/(1-Model!$B$9)/(1+Model!$B$18)^88)) | CY3: =IF(A3="","",IF((A3+89)>Model!$B$4,0,MAX(0,Model!$B$6-IF((A3+89)>=Model!$B$11,Model!$B$20,0)-IF(89<Model!$B$15,Model!$B$22,0))/(1-Model!$B$9)/(1+Model!$B$18)^89)) | CZ3: =IF(A3="","",IF((A3+90)>Model!$B$4,0,MAX(0,Model!$B$6-IF((A3+90)>=Model!$B$11,Model!$B$20,0)-IF(90<Model!$B$15,Model!$B$22,0))/(1-Model!$B$9)/(1+Model!$B$18)^90)) | DA3: =IF(A3="","",IF((A3+91)>Model!$B$4,0,MAX(0,Model!$B$6-IF((A3+91)>=Model!$B$11,Model!$B$20,0)-IF(91<Model!$B$15,Model!$B$22,0))/(1-Model!$B$9)/(1+Model!$B$18)^91)) | DB3: =IF(A3="","",IF((A3+92)>Model!$B$4,0,MAX(0,Model!$B$6-IF((A3+92)>=Model!$B$11,Model!$B$20,0)-IF(92<Model!$B$15,Model!$B$22,0))/(1-Model!$B$9)/(1+Model!$B$18)^92)) | DC3: =IF(A3="","",IF((A3+93)>Model!$B$4,0,MAX(0,Model!$B$6-IF((A3+93)>=Model!$B$11,Model!$B$20,0)-IF(93<Model!$B$15,Model!$B$22,0))/(1-Model!$B$9)/(1+Model!$B$18)^93)) | DD3: =IF(A3="","",IF((A3+94)>Model!$B$4,0,MAX(0,Model!$B$6-IF((A3+94)>=Model!$B$11,Model!$B$20,0)-IF(94<Model!$B$15,Model!$B$22,0))/(1-Model!$B$9)/(1+Model!$B$18)^94)) | DE3: =IF(A3="","",IF((A3+95)>Model!$B$4,0,MAX(0,Model!$B$6-IF((A3+95)>=Model!$B$11,Model!$B$20,0)-IF(95<Model!$B$15,Model!$B$22,0))/(1-Model!$B$9)/(1+Model!$B$18)^95)) | DF3: =IF(A3="","",IF((A3+96)>Model!$B$4,0,MAX(0,Model!$B$6-IF((A3+96)>=Model!$B$11,Model!$B$20,0)-IF(96<Model!$B$15,Model!$B$22,0))/(1-Model!$B$9)/(1+Model!$B$18)^96)) | DG3: =IF(A3="","",IF((A3+97)>Model!$B$4,0,MAX(0,Model!$B$6-IF((A3+97)>=Model!$B$11,Model!$B$20,0)-IF(97<Model!$B$15,Model!$B$22,0))/(1-Model!$B$9)/(1+Model!$B$18)^97)) | DH3: =IF(A3="","",IF((A3+98)>Model!$B$4,0,MAX(0,Model!$B$6-IF((A3+98)>=Model!$B$11,Model!$B$20,0)-IF(98<Model!$B$15,Model!$B$22,0))/(1-Model!$B$9)/(1+Model!$B$18)^98)) | DI3: =IF(A3="","",IF((A3+99)>Model!$B$4,0,MAX(0,Model!$B$6-IF((A3+99)>=Model!$B$11,Model!$B$20,0)-IF(99<Model!$B$15,Model!$B$22,0))/(1-Model!$B$9)/(1+Model!$B$18)^99)) | DJ3: =IF(A3="","",IF((A3+100)>Model!$B$4,0,MAX(0,Model!$B$6-IF((A3+100)>=Model!$B$11,Model!$B$20,0)-IF(100<Model!$B$15,Model!$B$22,0))/(1-Model!$B$9)/(1+Model!$B$18)^100)) | DK3: =IF(A3="","",IF((A3+101)>Model!$B$4,0,MAX(0,Model!$B$6-IF((A3+101)>=Model!$B$11,Model!$B$20,0)-IF(101<Model!$B$15,Model!$B$22,0))/(1-Model!$B$9)/(1+Model!$B$18)^101)) | DL3: =IF(A3="","",IF((A3+102)>Model!$B$4,0,MAX(0,Model!$B$6-IF((A3+102)>=Model!$B$11,Model!$B$20,0)-IF(102<Model!$B$15,Model!$B$22,0))/(1-Model!$B$9)/(1+Model!$B$18)^102)) | DM3: =IF(A3="","",IF((A3+103)>Model!$B$4,0,MAX(0,Model!$B$6-IF((A3+103)>=Model!$B$11,Model!$B$20,0)-IF(103<Model!$B$15,Model!$B$22,0))/(1-Model!$B$9)/(1+Model!$B$18)^103)) | DN3: =IF(A3="","",IF((A3+104)>Model!$B$4,0,MAX(0,Model!$B$6-IF((A3+104)>=Model!$B$11,Model!$B$20,0)-IF(104<Model!$B$15,Model!$B$22,0))/(1-Model!$B$9)/(1+Model!$B$18)^104)) | DO3: =IF(A3="","",IF((A3+105)>Model!$B$4,0,MAX(0,Model!$B$6-IF((A3+105)>=Model!$B$11,Model!$B$20,0)-IF(105<Model!$B$15,Model!$B$22,0))/(1-Model!$B$9)/(1+Model!$B$18)^105)) | DP3: =IF(A3="","",IF((A3+106)>Model!$B$4,0,MAX(0,Model!$B$6-IF((A3+106)>=Model!$B$11,Model!$B$20,0)-IF(106<Model!$B$15,Model!$B$22,0))/(1-Model!$B$9)/(1+Model!$B$18)^106)) | DQ3: =IF(A3="","",IF((A3+107)>Model!$B$4,0,MAX(0,Model!$B$6-IF((A3+107)>=Model!$B$11,Model!$B$20,0)-IF(107<Model!$B$15,Model!$B$22,0))/(1-Model!$B$9)/(1+Model!$B$18)^107)) | DR3: =IF(A3="","",IF((A3+108)>Model!$B$4,0,MAX(0,Model!$B$6-IF((A3+108)>=Model!$B$11,Model!$B$20,0)-IF(108<Model!$B$15,Model!$B$22,0))/(1-Model!$B$9)/(1+Model!$B$18)^108)) | DS3: =IF(A3="","",IF((A3+109)>Model!$B$4,0,MAX(0,Model!$B$6-IF((A3+109)>=Model!$B$11,Model!$B$20,0)-IF(109<Model!$B$15,Model!$B$22,0))/(1-Model!$B$9)/(1+Model!$B$18)^109)) | DT3: =IF(A3="","",IF((A3+110)>Model!$B$4,0,MAX(0,Model!$B$6-IF((A3+110)>=Model!$B$11,Model!$B$20,0)-IF(110<Model!$B$15,Model!$B$22,0))/(1-Model!$B$9)/(1+Model!$B$18)^110)) | DU3: =IF(A3="","",IF((A3+111)>Model!$B$4,0,MAX(0,Model!$B$6-IF((A3+111)>=Model!$B$11,Model!$B$20,0)-IF(111<Model!$B$15,Model!$B$22,0))/(1-Model!$B$9)/(1+Model!$B$18)^111)) | DV3: =IF(A3="","",IF((A3+112)>Model!$B$4,0,MAX(0,Model!$B$6-IF((A3+112)>=Model!$B$11,Model!$B$20,0)-IF(112<Model!$B$15,Model!$B$22,0))/(1-Model!$B$9)/(1+Model!$B$18)^112)) | DW3: =IF(A3="","",IF((A3+113)>Model!$B$4,0,MAX(0,Model!$B$6-IF((A3+113)>=Model!$B$11,Model!$B$20,0)-IF(113<Model!$B$15,Model!$B$22,0))/(1-Model!$B$9)/(1+Model!$B$18)^113)) | DX3: =IF(A3="","",IF((A3+114)>Model!$B$4,0,MAX(0,Model!$B$6-IF((A3+114)>=Model!$B$11,Model!$B$20,0)-IF(114<Model!$B$15,Model!$B$22,0))/(1-Model!$B$9)/(1+Model!$B$18)^114)) | DY3: =IF(A3="","",IF((A3+115)>Model!$B$4,0,MAX(0,Model!$B$6-IF((A3+115)>=Model!$B$11,Model!$B$20,0)-IF(115<Model!$B$15,Model!$B$22,0))/(1-Model!$B$9)/(1+Model!$B$18)^115)) | DZ3: =IF(A3="","",IF((A3+116)>Model!$B$4,0,MAX(0,Model!$B$6-IF((A3+116)>=Model!$B$11,Model!$B$20,0)-IF(116<Model!$B$15,Model!$B$22,0))/(1-Model!$B$9)/(1+Model!$B$18)^116)) | EA3: =IF(A3="","",IF((A3+117)>Model!$B$4,0,MAX(0,Model!$B$6-IF((A3+117)>=Model!$B$11,Model!$B$20,0)-IF(117<Model!$B$15,Model!$B$22,0))/(1-Model!$B$9)/(1+Model!$B$18)^117)) | EB3: =IF(A3="","",IF((A3+118)>Model!$B$4,0,MAX(0,Model!$B$6-IF((A3+118)>=Model!$B$11,Model!$B$20,0)-IF(118<Model!$B$15,Model!$B$22,0))/(1-Model!$B$9)/(1+Model!$B$18)^118)) | EC3: =IF(A3="","",IF((A3+119)>Model!$B$4,0,MAX(0,Model!$B$6-IF((A3+119)>=Model!$B$11,Model!$B$20,0)-IF(119<Model!$B$15,Model!$B$22,0))/(1-Model!$B$9)/(1+Model!$B$18)^119)) | ED3: =IF(A3="","",IF((A3+120)>Model!$B$4,0,MAX(0,Model!$B$6-IF((A3+120)>=Model!$B$11,Model!$B$20,0)-IF(120<Model!$B$15,Model!$B$22,0))/(1-Model!$B$9)/(1+Model!$B$18)^120))
